Workbook

Sheet README
A1: SUMEEPER FEAST SHEET — แยกหน้า Art ออกจาก Data + ปรับให้ตรงกับ Equipment Design B
A3: โครงสร้างชีต (ลำดับซ้าย→ขวา)
A4: • Monsters Config — DATA ล้วน ไม่มีคอลัมน์ภาพแล้ว: Key/Tier/ชื่อ/Name/HP/ATK/DEF/SPD/Stat Sum/ความสามารถ/ของดรอบ/Note
A5: • Feast Art — หน้าใหม่: Key + ภาพตัวหลักตอนสู้ + ภาพตัวจิ๋วในแมพ + ชื่อ + รายละเอียด (ภาพทั้ง 31 ย้ายมาที่นี่)
A6: • Weights (Feast) — weight tables ฝั่ง Feast
A7: • Feast — สรุป CP (ดึง stat จาก Monsters Config ด้วยลิงก์สีเขียว)
A8: • Feast Sequence — 1 แถว = 1 action
A9: • Feast Ability — 1 แถว = 1 ability (โครงเดียวกับ Ability ของ Equipment)
A11: การแยกหน้า Art / Data
A12: • ภาพ embedded ทั้งหมดอยู่บนหน้า Feast Art (คอลัมน์ B, C) — Monsters Config ไม่มีภาพแล้ว
A13: • ทั้งสองหน้าเชื่อมกันด้วย Key (คอลัมน์ A) — เพิ่ม/ลบตัว ให้ sync Key ให้ตรงกันทั้งสองหน้า
A15: สี
... A34: • Eater ตั้ง Scope=Combat ไว้ก่อน — รอ confirm

Sheet Monsters Config
A1: Key | B1: Tier | C1: ชื่อ (TH) | D1: Name (EN) | E1: HP | F1: ATK | G1: DEF | H1: SPD | I1: Stat Sum | J1: ความสามารถ (raw) | K1: ของดรอบ | L1: Note
A2: MONSTER_ORANGECAT | B2: 1 | C2: แงวส้ม | D2: Orange Cat | E2: 7 | F2: 2 | G2: 1 | H2: 2 | I2: =E2*1+F2*3+G2*3+H2*2 -> 20 | K2: ผัก * 1 ชิ้น
A3: MONSTER_ONPIRENION | B3: 1 | C3: หัวหอมแดรกคูลา | D3: Onpirenion | E3: 6 | F3: 1 | G3: 1 | H3: 4 | I3: =E3*1+F3*3+G3*3+H3*2 -> 20 | K3: เครื่องเทศ * 1 ชิ้น
A4: MONSTER_MUSHROOMRAT | B4: 1 | C4: หนูหูเห็ด | D4: Mushroom Rat | E4: 9 | F4: 1 | G4: 2 | H4: 1 | I4: =E4*1+F4*3+G4*3+H4*2 -> 20 | K4: เนื้อ * 1 ชิ้น
A5: MONSTER_CABBAGEDOG | B5: 1 | C5: หมาผักกาด | D5: Cabbage dog | E5: 2 | F5: 1 | G5: 1 | H5: 6 | I5: =E5*1+F5*3+G5*3+H5*2 -> 20 | K5: เนื้อ * 1 ชิ้น
A6: MONSTER_CHERRYBIRD | B6: 2 | C6: นกเชอรี่ | D6: Cherry Bird | E6: 12 | F6: 4 | G6: 4 | H6: 2 | I6: =E6*1+F6*3+G6*3+H6*2 -> 40 | J6: - Death Freezer 2 | K6: ผัก * 1 ชิ้น
A7: MONSTER_PUDDINGCRAP | B7: 2 | C7: ปู๊ดดิ้ง | D7: Pudding Crab | E7: 17 | F7: 3 | G7: 4 | H7: 1 | I7: =E7*1+F7*3+G7*3+H7*2 -> 40 | J7: - On-Hit Gain 1 DEF | K7: เนื้อ * 1 ชิ้น
A8: MONSTER_SUGARTIGER | B8: 2 | C8: เสื้อโฮกน้ำตาลปี๊บ | D8: Sugar Tiger | E8: 8 | F8: 4 | G8: 2 | H8: 7 | I8: =E8*1+F8*3+G8*3+H8*2 -> 40 | J8: - On-Hit Gain 1 ATK | K8: เครื่องเทศ * 1 ชิ้น
A9: MONSTER_SPICYHEDGEHOG | B9: 3 | C9: เม่นพริก | D9: Spicy Hedgehog | E9: 12 | F9: 5 | G9: 7 | H9: 6 | I9: =E9*1+F9*3+G9*3+H9*2 -> 60 | J9: - Battlecry Taunt 2 - On-Damage Gain 2 ATK | K9: เครื่องเทศ * 1 ชิ้น
A10: MONSTER_BLUEFIN | B10: 3 | C10: ปลาทูเพื่อนรัก | D10: Bluefin In love | E10: 16 | F10: 4 | G10: 6 | H10: 7 | I10: =E10*1+F10*3+G10*3+H10*2 -> 60 | J10: - Battlecry Freezer 2 - On-Damage Convert 3 HP to 1 speed | K10: เนื้อ * 1 ชิ้น เครื่องเทศ * 1 ชิ้น
A11: MONSTER_PIZZATURTLE | B11: 3 | C11: เต่าพิซซ่า | D11: Pizza Turtle | E11: 25 | F11: 4 | G11: 7 | H11: 1 | I11: =E11*1+F11*3+G11*3+H11*2 -> 60 | J11: - Battlecry Taunt 3 - On-Damage Armor 1 | K11: มีโอกาส 50% ที่จะได้ เนื้อ * 1 ชิ้น , ผัก * 1 ชิ้น , เครื่องเทศ * 1 ชิ้น
A12: MONSTER_DURAINBOMB | B12: 3 | C12: ทุเรียนระเบิด | D12: Durain Bomb | E12: 14 | F12: 6 | G12: 8 | H12: 2 | I12: =E12*1+F12*3+G12*3+H12*2 -> 60 | J12: - On-Start Thorn 1 - On-Hit Eater 1 | K12: ผัก * 1 ชิ้น
A13: MONSTER_CHIVE | B13: 3 | C13: กุ้ยช่ายสด | E13: 6 | F13: 5 | G13: 8 | H13: 12 | I13: =E13*1+F13*3+G13*3+H13*2 -> 69 | J13: - Death Freezer 2 - On-Hit Gain 1 ATK | K13: ผัก * 1 ชิ้น
A14: MONSTER_BROCOLION | B14: 4 | C14: สิงโตบล็อคโคลี่ | D14: BrocoLion | E14: 20 | F14: 8 | G14: 6 | H14: 9 | I14: =E14*1+F14*3+G14*3+H14*2 -> 80 | J14: - On-Exposed Gain 2 ATK - On-Half Gain 2 SPD | K14: ผัก * 2 ชิ้น
A15: MONSTER_BANANAOCTOPUS | B15: 4 | C15: หมึกกล้วย | D15: Banana Octopus | E15: 27 | F15: 6 | G15: 5 | H15: 10 | I15: =E15*1+F15*3+G15*3+H15*2 -> 80 | J15: - Battlecry Taunt 2 - On-Damage Gain 2 ATK | K15: เนื้อ * 2 ชิ้น
A16: MONSTER_UBEECORN | B16: 4 | C16: ยูบีคอร์น | D16: Ubeecorn | E16: 17 | F16: 9 | G16: 2 | H16: 15 | I16: =E16*1+F16*3+G16*3+H16*2 -> 80 | J16: - On-Hit Restore 2 - On-Half Shield 1 | K16: มีโอกาส 75% ที่จะได้ เนื้อ * 1 ชิ้น , ผัก * 1 ชิ้น , เครื่องเทศ * 1 ชิ้น
A17: MONSTER_MONKEYCUPSSPICES | B17: 4 | C17: ต้นหม้อข้าวหม้อแกง | D17: MonkeyCupsSpices | E17: 24 | F17: 6 | G17: 8 | H17: 7 | I17: =E17*1+F17*3+G17*3+H17*2 -> 80 | J17: - Battlecry Freezer 2 - On-Half Thorn 2 | K17: ผัก * 2 ชิ้น
A18: MONSTER_DEARBOKCHOY | B18: 5 | C18: กวางตุ้งฮ่องเต้ | D18: DearBokchoy | E18: 50 | F18: 5 | G18: 5 | H18: 10 | I18: =E18*1+F18*3+G18*3+H18*2 -> 100 | J18: - Battlecry Freezer 3 - On-Start Thorn 2 - On-Hit Restore 2 | K18: เนื้อ * 2 ชิ้น เครื่องเทศ * 2 ชิ้น
A19: MONSTER_JELLYUDON | B19: 5 | C19: แมงกะพรุนอูด้ง | D19: Jelly Udon | E19: 40 | F19: 10 | G19: 6 | H19: 6 | I19: =E19*1+F19*3+G19*3+H19*2 -> 100 | J19: - Battlecry Taunt 3 - On-Exposed Thorn 2 - On-Half Armor 2 | K19: เนื้อ * 2 ชิ้น เครื่องเทศ * 1 ชิ้น ผัก * 1 ชิ้น

Sheet Feast Art
A1: Key | B1: ตัวหลักตอนสู้ | C1: ตัวจิ๋วในแมพ | D1: ชื่อ (TH) | E1: Name (EN) | F1: รายละเอียด
A3: MONSTER_ORANGECAT | D3: แงวส้ม | E3: Orange Cat | F3: แมว+ส้ม
A4: MONSTER_ONPIRENION | D4: หัวหอมแดรกคูลา | E4: Onpirenion | F4: ค้างคาว+หัวหอม
A5: MONSTER_MUSHROOMRAT | D5: หนูหูเห็ด | E5: Mushroom Rat | F5: หนู+เห้ดหูหนู
A6: MONSTER_CABBAGEDOG | D6: หมาผักกาด | E6: Cabbage dog | F6: หมา+ผักกาด (อาจจะซ้ำ ออกแบบใหม่ได้)
A7: MONSTER_CHERRYBIRD | D7: นกเชอรี่ | E7: Cherry Bird | F7: นก + เชอร์รี่
A8: MONSTER_PUDDINGCRAP | D8: ปู๊ดดิ้ง | E8: Pudding Crab | F8: ปู + พุดดิ้ง
A9: MONSTER_SUGARTIGER | D9: เสื้อโฮกน้ำตาลปี๊บ | E9: Sugar Tiger | F9: เสือ + ชานมไข่มุก
A10: MONSTER_SPICYHEDGEHOG | D10: เม่นพริก | E10: Spicy Hedgehog | F10: เม่น + พริก
A11: MONSTER_BLUEFIN | D11: ปลาทูเพื่อนรัก | E11: Bluefin In love | F11: ปลาทูแม่กลอง
A12: MONSTER_PIZZATURTLE | D12: เต่าพิซซ่า | E12: Pizza Turtle | F12: เต่า + พิซซ่า
A13: MONSTER_DURAINBOMB | D13: ทุเรียนระเบิด | E13: Durain Bomb | F13: ทุเรียน + ระเบิด
A14: MONSTER_CHIVE | D14: กุ้ยช่ายสด | F14: แค่กุ้ยช่ายมีชีวิต
A15: MONSTER_BROCOLION | D15: สิงโตบล็อคโคลี่ | E15: BrocoLion | F15: สิงโต + บล็อกโคลี่
A16: MONSTER_BANANAOCTOPUS | D16: หมึกกล้วย | E16: Banana Octopus | F16: หมึก + กล้วย
A17: MONSTER_UBEECORN | D17: ยูบีคอร์น | E17: Ubeecorn | F17: ผึ้ง + สายไหม
A18: MONSTER_MONKEYCUPSSPICES | D18: ต้นหม้อข้าวหม้อแกง | E18: MonkeyCupsSpices | F18: หม้อข้าวหม้อแกงลิง + ขวดเครื่องปรุง
A19: MONSTER_DEARBOKCHOY | D19: กวางตุ้งฮ่องเต้ | E19: DearBokchoy | F19: กวาง + กวางตุ้งฮ่องเต้
A20: MONSTER_JELLYUDON | D20: แมงกะพรุนอูด้ง | E20: Jelly Udon | F20: แม่งกระพรุน + อูด้ง

Sheet Weights (Feast)
A1: WEIGHT TABLES — FEAST (แก้ค่าสีน้ำเงินเพื่อ tune) | C1: พื้นเหลืองเข้ม = weight ที่ยังไม่เคยมี ตั้งค่าเริ่มต้นไว้ ต้อง tune จาก playtest
A3: Tier Stat Budget
A4: 1 | B4: 20
A5: 2 | B5: 40
A6: 3 | B6: 60
A7: 4 | B7: 80
A8: 5 | B8: 100
A10: Tier CP Budget
A11: 1 | B11: 20
A12: 2 | B12: 40
A13: 3 | B13: 60
A14: 4 | B14: 80
A15: 5 | B15: 100
A17: Stat Weight (for Stat Sum)
A18: HP | B18: 1
A19: ATK | B19: 3
A20: DEF | B20: 3
A21: SPD | B21: 2
A23: Trigger Weight
A24: Passive | B24: 0
A25: On-Start | B25: 2
A26: Battlecry | B26: 2
A27: Death | B27: 1.5
A28: On-Half | B28: 1.5
A29: On-Exposed | B29: 1.5
A30: Special | B30: 2.5
A31: On-Damaged | B31: 3
A32: On-Hit | B32: 4
A34: Verb Weight
A35: Lose | B35: -1.5
A36: Restore | B36: 1.5
A37: Gain | B37: 1.5
A38: Convert | B38: 1.5
A39: Taunt | B39: 2
A40: Armor | B40: 2.5
A41: Shield | B41: 2.5
A42: Thorn | B42: 3
A43: Freezer | B43: 3
A44: Eater | B44: 3
A45: Fury | B45: 3.5
...

Sheet Feast
A1: Key | B1: Tier | C1: ชื่อ (TH) | D1: Name (EN) | E1: HP | F1: DEF | G1: SPD | H1: Max AG | I1: Actions | J1: Total ATK | K1: Total Charge | L1: Stat Sum | M1: Stat Budget | N1: dStat | O1: Ability Value | P1: Special Rate | Q1: Charge Value | R1: Combat Power | S1: CP Budget | T1: dCP
A2: ='Monsters Config'!A2 -> MONSTER_ORANGECAT | B2: ='Monsters Config'!B2 -> 1 | C2: ='Monsters Config'!C2 -> แงวส้ม | D2: ='Monsters Config'!D2 -> Orange Cat | E2: ='Monsters Config'!E2 -> 7 | F2: ='Monsters Config'!G2 -> 1 | G2: ='Monsters Config'!H2 -> 2 | H2: 2 | I2: =COUNTIF('Feast Sequence'!$A:$A,$A2) -> 1 | J2: =SUMIF('Feast Sequence'!$A:$A,$A2,'Feast Sequence'!$E:$E) -> 2 | K2: =SUMIF('Feast Sequence'!$A:$A,$A2,'Feast Sequence'!$F:$F) -> 1 | L2: =E2*'Weights (Feast)'!$B$18+J2*'Weights (Feast)'!$B$19+F2*'Weights (Feast)'!$B$20+G2*'Weights (Feast)'!$B$21 -> 20 | M2: =VLOOKUP(B2,'Weights (Feast)'!$A$4:$B$8,2,FALSE()) -> 20 | N2: =L2-M2 -> 0 | O2: =SUMIF('Feast Combat Ability'!$A:$A,$A2,'Feast Combat Ability'!$K:$K) -> 0 | P2: =IF(H2=0,0,K2/H2) -> 0.5 | Q2: =IF(COUNTIFS('Feast Combat Ability'!$A:$A,$A2,'Feast Combat Ability'!$C:$C,"Special")=0,0,P2*'Weights (Feast)'!$B$75) -> 0 | R2: =L2+O2+Q2 -> 20 | S2: =VLOOKUP(B2,'Weights (Feast)'!$A$11:$B$15,2,FALSE()) -> 20 | T2: =R2-S2 -> 0
A3: ='Monsters Config'!A3 -> MONSTER_ONPIRENION | B3: ='Monsters Config'!B3 -> 1 | C3: ='Monsters Config'!C3 -> หัวหอมแดรกคูลา | D3: ='Monsters Config'!D3 -> Onpirenion | E3: ='Monsters Config'!E3 -> 6 | F3: ='Monsters Config'!G3 -> 1 | G3: ='Monsters Config'!H3 -> 4 | H3: 2 | I3: =COUNTIF('Feast Sequence'!$A:$A,$A3) -> 1 | J3: =SUMIF('Feast Sequence'!$A:$A,$A3,'Feast Sequence'!$E:$E) -> 1 | K3: =SUMIF('Feast Sequence'!$A:$A,$A3,'Feast Sequence'!$F:$F) -> 1 | L3: =E3*'Weights (Feast)'!$B$18+J3*'Weights (Feast)'!$B$19+F3*'Weights (Feast)'!$B$20+G3*'Weights (Feast)'!$B$21 -> 20 | M3: =VLOOKUP(B3,'Weights (Feast)'!$A$4:$B$8,2,FALSE()) -> 20 | N3: =L3-M3 -> 0 | O3: =SUMIF('Feast Combat Ability'!$A:$A,$A3,'Feast Combat Ability'!$K:$K) -> 0 | P3: =IF(H3=0,0,K3/H3) -> 0.5 | Q3: =IF(COUNTIFS('Feast Combat Ability'!$A:$A,$A3,'Feast Combat Ability'!$C:$C,"Special")=0,0,P3*'Weights (Feast)'!$B$75) -> 0 | R3: =L3+O3+Q3 -> 20 | S3: =VLOOKUP(B3,'Weights (Feast)'!$A$11:$B$15,2,FALSE()) -> 20 | T3: =R3-S3 -> 0
A4: ='Monsters Config'!A4 -> MONSTER_MUSHROOMRAT | B4: ='Monsters Config'!B4 -> 1 | C4: ='Monsters Config'!C4 -> หนูหูเห็ด | D4: ='Monsters Config'!D4 -> Mushroom Rat | E4: ='Monsters Config'!E4 -> 9 | F4: ='Monsters Config'!G4 -> 2 | G4: ='Monsters Config'!H4 -> 1 | H4: 2 | I4: =COUNTIF('Feast Sequence'!$A:$A,$A4) -> 1 | J4: =SUMIF('Feast Sequence'!$A:$A,$A4,'Feast Sequence'!$E:$E) -> 1 | K4: =SUMIF('Feast Sequence'!$A:$A,$A4,'Feast Sequence'!$F:$F) -> 1 | L4: =E4*'Weights (Feast)'!$B$18+J4*'Weights (Feast)'!$B$19+F4*'Weights (Feast)'!$B$20+G4*'Weights (Feast)'!$B$21 -> 20 | M4: =VLOOKUP(B4,'Weights (Feast)'!$A$4:$B$8,2,FALSE()) -> 20 | N4: =L4-M4 -> 0 | O4: =SUMIF('Feast Combat Ability'!$A:$A,$A4,'Feast Combat Ability'!$K:$K) -> 0 | P4: =IF(H4=0,0,K4/H4) -> 0.5 | Q4: =IF(COUNTIFS('Feast Combat Ability'!$A:$A,$A4,'Feast Combat Ability'!$C:$C,"Special")=0,0,P4*'Weights (Feast)'!$B$75) -> 0 | R4: =L4+O4+Q4 -> 20 | S4: =VLOOKUP(B4,'Weights (Feast)'!$A$11:$B$15,2,FALSE()) -> 20 | T4: =R4-S4 -> 0
A5: ='Monsters Config'!A5 -> MONSTER_CABBAGEDOG | B5: ='Monsters Config'!B5 -> 1 | C5: ='Monsters Config'!C5 -> หมาผักกาด | D5: ='Monsters Config'!D5 -> Cabbage dog | E5: ='Monsters Config'!E5 -> 2 | F5: ='Monsters Config'!G5 -> 1 | G5: ='Monsters Config'!H5 -> 6 | H5: 2 | I5: =COUNTIF('Feast Sequence'!$A:$A,$A5) -> 1 | J5: =SUMIF('Feast Sequence'!$A:$A,$A5,'Feast Sequence'!$E:$E) -> 1 | K5: =SUMIF('Feast Sequence'!$A:$A,$A5,'Feast Sequence'!$F:$F) -> 1 | L5: =E5*'Weights (Feast)'!$B$18+J5*'Weights (Feast)'!$B$19+F5*'Weights (Feast)'!$B$20+G5*'Weights (Feast)'!$B$21 -> 20 | M5: =VLOOKUP(B5,'Weights (Feast)'!$A$4:$B$8,2,FALSE()) -> 20 | N5: =L5-M5 -> 0 | O5: =SUMIF('Feast Combat Ability'!$A:$A,$A5,'Feast Combat Ability'!$K:$K) -> 0 | P5: =IF(H5=0,0,K5/H5) -> 0.5 | Q5: =IF(COUNTIFS('Feast Combat Ability'!$A:$A,$A5,'Feast Combat Ability'!$C:$C,"Special")=0,0,P5*'Weights (Feast)'!$B$75) -> 0 | R5: =L5+O5+Q5 -> 20 | S5: =VLOOKUP(B5,'Weights (Feast)'!$A$11:$B$15,2,FALSE()) -> 20 | T5: =R5-S5 -> 0
A6: ='Monsters Config'!A6 -> MONSTER_CHERRYBIRD | B6: ='Monsters Config'!B6 -> 2 | C6: ='Monsters Config'!C6 -> นกเชอรี่ | D6: ='Monsters Config'!D6 -> Cherry Bird | E6: ='Monsters Config'!E6 -> 12 | F6: ='Monsters Config'!G6 -> 4 | G6: ='Monsters Config'!H6 -> 2 | H6: 2 | I6: =COUNTIF('Feast Sequence'!$A:$A,$A6) -> 2 | J6: =SUMIF('Feast Sequence'!$A:$A,$A6,'Feast Sequence'!$E:$E) -> 4 | K6: =SUMIF('Feast Sequence'!$A:$A,$A6,'Feast Sequence'!$F:$F) -> 2 | L6: =E6*'Weights (Feast)'!$B$18+J6*'Weights (Feast)'!$B$19+F6*'Weights (Feast)'!$B$20+G6*'Weights (Feast)'!$B$21 -> 40 | M6: =VLOOKUP(B6,'Weights (Feast)'!$A$4:$B$8,2,FALSE()) -> 40 | N6: =L6-M6 -> 0 | O6: =SUMIF('Feast Combat Ability'!$A:$A,$A6,'Feast Combat Ability'!$K:$K) -> 0 | P6: =IF(H6=0,0,K6/H6) -> 1 | Q6: =IF(COUNTIFS('Feast Combat Ability'!$A:$A,$A6,'Feast Combat Ability'!$C:$C,"Special")=0,0,P6*'Weights (Feast)'!$B$75) -> 0 | R6: =L6+O6+Q6 -> 40 | S6: =VLOOKUP(B6,'Weights (Feast)'!$A$11:$B$15,2,FALSE()) -> 40 | T6: =R6-S6 -> 0
A7: ='Monsters Config'!A7 -> MONSTER_PUDDINGCRAP | B7: ='Monsters Config'!B7 -> 2 | C7: ='Monsters Config'!C7 -> ปู๊ดดิ้ง | D7: ='Monsters Config'!D7 -> Pudding Crab | E7: ='Monsters Config'!E7 -> 17 | F7: ='Monsters Config'!G7 -> 4 | G7: ='Monsters Config'!H7 -> 1 | H7: 2 | I7: =COUNTIF('Feast Sequence'!$A:$A,$A7) -> 2 | J7: =SUMIF('Feast Sequence'!$A:$A,$A7,'Feast Sequence'!$E:$E) -> 3 | K7: =SUMIF('Feast Sequence'!$A:$A,$A7,'Feast Sequence'!$F:$F) -> 2 | L7: =E7*'Weights (Feast)'!$B$18+J7*'Weights (Feast)'!$B$19+F7*'Weights (Feast)'!$B$20+G7*'Weights (Feast)'!$B$21 -> 40 | M7: =VLOOKUP(B7,'Weights (Feast)'!$A$4:$B$8,2,FALSE()) -> 40 | N7: =L7-M7 -> 0 | O7: =SUMIF('Feast Combat Ability'!$A:$A,$A7,'Feast Combat Ability'!$K:$K) -> 2.8125 | P7: =IF(H7=0,0,K7/H7) -> 1 | Q7: =IF(COUNTIFS('Feast Combat Ability'!$A:$A,$A7,'Feast Combat Ability'!$C:$C,"Special")=0,0,P7*'Weights (Feast)'!$B$75) -> 0 | R7: =L7+O7+Q7 -> 42.8125 | S7: =VLOOKUP(B7,'Weights (Feast)'!$A$11:$B$15,2,FALSE()) -> 40 | T7: =R7-S7 -> 2.8125
A8: ='Monsters Config'!A8 -> MONSTER_SUGARTIGER | B8: ='Monsters Config'!B8 -> 2 | C8: ='Monsters Config'!C8 -> เสื้อโฮกน้ำตาลปี๊บ | D8: ='Monsters Config'!D8 -> Sugar Tiger | E8: ='Monsters Config'!E8 -> 8 | F8: ='Monsters Config'!G8 -> 2 | G8: ='Monsters Config'!H8 -> 7 | H8: 2 | I8: =COUNTIF('Feast Sequence'!$A:$A,$A8) -> 2 | J8: =SUMIF('Feast Sequence'!$A:$A,$A8,'Feast Sequence'!$E:$E) -> 4 | K8: =SUMIF('Feast Sequence'!$A:$A,$A8,'Feast Sequence'!$F:$F) -> 2 | L8: =E8*'Weights (Feast)'!$B$18+J8*'Weights (Feast)'!$B$19+F8*'Weights (Feast)'!$B$20+G8*'Weights (Feast)'!$B$21 -> 40 | M8: =VLOOKUP(B8,'Weights (Feast)'!$A$4:$B$8,2,FALSE()) -> 40 | N8: =L8-M8 -> 0 | O8: =SUMIF('Feast Combat Ability'!$A:$A,$A8,'Feast Combat Ability'!$K:$K) -> 3.75 | P8: =IF(H8=0,0,K8/H8) -> 1 | Q8: =IF(COUNTIFS('Feast Combat Ability'!$A:$A,$A8,'Feast Combat Ability'!$C:$C,"Special")=0,0,P8*'Weights (Feast)'!$B$75) -> 0 | R8: =L8+O8+Q8 -> 43.75 | S8: =VLOOKUP(B8,'Weights (Feast)'!$A$11:$B$15,2,FALSE()) -> 40 | T8: =R8-S8 -> 3.75
A9: ='Monsters Config'!A9 -> MONSTER_SPICYHEDGEHOG | B9: ='Monsters Config'!B9 -> 3 | C9: ='Monsters Config'!C9 -> เม่นพริก | D9: ='Monsters Config'!D9 -> Spicy Hedgehog | E9: ='Monsters Config'!E9 -> 12 | F9: ='Monsters Config'!G9 -> 7 | G9: ='Monsters Config'!H9 -> 6 | H9: 2 | I9: =COUNTIF('Feast Sequence'!$A:$A,$A9) -> 2 | J9: =SUMIF('Feast Sequence'!$A:$A,$A9,'Feast Sequence'!$E:$E) -> 5 | K9: =SUMIF('Feast Sequence'!$A:$A,$A9,'Feast Sequence'!$F:$F) -> 2 | L9: =E9*'Weights (Feast)'!$B$18+J9*'Weights (Feast)'!$B$19+F9*'Weights (Feast)'!$B$20+G9*'Weights (Feast)'!$B$21 -> 60 | M9: =VLOOKUP(B9,'Weights (Feast)'!$A$4:$B$8,2,FALSE()) -> 60 | N9: =L9-M9 -> 0 | O9: =SUMIF('Feast Combat Ability'!$A:$A,$A9,'Feast Combat Ability'!$K:$K) -> 10.125 | P9: =IF(H9=0,0,K9/H9) -> 1 | Q9: =IF(COUNTIFS('Feast Combat Ability'!$A:$A,$A9,'Feast Combat Ability'!$C:$C,"Special")=0,0,P9*'Weights (Feast)'!$B$75) -> 0 | R9: =L9+O9+Q9 -> 70.125 | S9: =VLOOKUP(B9,'Weights (Feast)'!$A$11:$B$15,2,FALSE()) -> 60 | T9: =R9-S9 -> 10.125
A10: ='Monsters Config'!A10 -> MONSTER_BLUEFIN | B10: ='Monsters Config'!B10 -> 3 | C10: ='Monsters Config'!C10 -> ปลาทูเพื่อนรัก | D10: ='Monsters Config'!D10 -> Bluefin In love | E10: ='Monsters Config'!E10 -> 16 | F10: ='Monsters Config'!G10 -> 6 | G10: ='Monsters Config'!H10 -> 7 | H10: 3 | I10: =COUNTIF('Feast Sequence'!$A:$A,$A10) -> 2 | J10: =SUMIF('Feast Sequence'!$A:$A,$A10,'Feast Sequence'!$E:$E) -> 4 | K10: =SUMIF('Feast Sequence'!$A:$A,$A10,'Feast Sequence'!$F:$F) -> 2 | L10: =E10*'Weights (Feast)'!$B$18+J10*'Weights (Feast)'!$B$19+F10*'Weights (Feast)'!$B$20+G10*'Weights (Feast)'!$B$21 -> 60 | M10: =VLOOKUP(B10,'Weights (Feast)'!$A$4:$B$8,2,FALSE()) -> 60 | N10: =L10-M10 -> 0 | O10: =SUMIF('Feast Combat Ability'!$A:$A,$A10,'Feast Combat Ability'!$K:$K) -> 18 | P10: =IF(H10=0,0,K10/H10) -> 0.66666667 | Q10: =IF(COUNTIFS('Feast Combat Ability'!$A:$A,$A10,'Feast Combat Ability'!$C:$C,"Special")=0,0,P10*'Weights (Feast)'!$B$75) -> 0 | R10: =L10+O10+Q10 -> 78 | S10: =VLOOKUP(B10,'Weights (Feast)'!$A$11:$B$15,2,FALSE()) -> 60 | T10: =R10-S10 -> 18
A11: ='Monsters Config'!A11 -> MONSTER_PIZZATURTLE | B11: ='Monsters Config'!B11 -> 3 | C11: ='Monsters Config'!C11 -> เต่าพิซซ่า | D11: ='Monsters Config'!D11 -> Pizza Turtle | E11: ='Monsters Config'!E11 -> 25 | F11: ='Monsters Config'!G11 -> 7 | G11: ='Monsters Config'!H11 -> 1 | H11: 2 | I11: =COUNTIF('Feast Sequence'!$A:$A,$A11) -> 2 | J11: =SUMIF('Feast Sequence'!$A:$A,$A11,'Feast Sequence'!$E:$E) -> 4 | K11: =SUMIF('Feast Sequence'!$A:$A,$A11,'Feast Sequence'!$F:$F) -> 2 | L11: =E11*'Weights (Feast)'!$B$18+J11*'Weights (Feast)'!$B$19+F11*'Weights (Feast)'!$B$20+G11*'Weights (Feast)'!$B$21 -> 60 | M11: =VLOOKUP(B11,'Weights (Feast)'!$A$4:$B$8,2,FALSE()) -> 60 | N11: =L11-M11 -> 0 | O11: =SUMIF('Feast Combat Ability'!$A:$A,$A11,'Feast Combat Ability'!$K:$K) -> 11.25 | P11: =IF(H11=0,0,K11/H11) -> 1 | Q11: =IF(COUNTIFS('Feast Combat Ability'!$A:$A,$A11,'Feast Combat Ability'!$C:$C,"Special")=0,0,P11*'Weights (Feast)'!$B$75) -> 0 | R11: =L11+O11+Q11 -> 71.25 | S11: =VLOOKUP(B11,'Weights (Feast)'!$A$11:$B$15,2,FALSE()) -> 60 | T11: =R11-S11 -> 11.25
A12: ='Monsters Config'!A12 -> MONSTER_DURAINBOMB | B12: ='Monsters Config'!B12 -> 3 | C12: ='Monsters Config'!C12 -> ทุเรียนระเบิด | D12: ='Monsters Config'!D12 -> Durain Bomb | E12: ='Monsters Config'!E12 -> 14 | F12: ='Monsters Config'!G12 -> 8 | G12: ='Monsters Config'!H12 -> 2 | H12: 3 | I12: =COUNTIF('Feast Sequence'!$A:$A,$A12) -> 2 | J12: =SUMIF('Feast Sequence'!$A:$A,$A12,'Feast Sequence'!$E:$E) -> 6 | K12: =SUMIF('Feast Sequence'!$A:$A,$A12,'Feast Sequence'!$F:$F) -> 2 | L12: =E12*'Weights (Feast)'!$B$18+J12*'Weights (Feast)'!$B$19+F12*'Weights (Feast)'!$B$20+G12*'Weights (Feast)'!$B$21 -> 60 | M12: =VLOOKUP(B12,'Weights (Feast)'!$A$4:$B$8,2,FALSE()) -> 60 | N12: =L12-M12 -> 0 | O12: =SUMIF('Feast Combat Ability'!$A:$A,$A12,'Feast Combat Ability'!$K:$K) -> 27 | P12: =IF(H12=0,0,K12/H12) -> 0.66666667 | Q12: =IF(COUNTIFS('Feast Combat Ability'!$A:$A,$A12,'Feast Combat Ability'!$C:$C,"Special")=0,0,P12*'Weights (Feast)'!$B$75) -> 0 | R12: =L12+O12+Q12 -> 87 | S12: =VLOOKUP(B12,'Weights (Feast)'!$A$11:$B$15,2,FALSE()) -> 60 | T12: =R12-S12 -> 27
A13: ='Monsters Config'!A13 -> MONSTER_CHIVE | B13: ='Monsters Config'!B13 -> 3 | C13: ='Monsters Config'!C13 -> กุ้ยช่ายสด | D13: ='Monsters Config'!D13 | E13: ='Monsters Config'!E13 -> 6 | F13: ='Monsters Config'!G13 -> 8 | G13: ='Monsters Config'!H13 -> 12 | H13: 2 | I13: =COUNTIF('Feast Sequence'!$A:$A,$A13) -> 2 | J13: =SUMIF('Feast Sequence'!$A:$A,$A13,'Feast Sequence'!$E:$E) -> 5 | K13: =SUMIF('Feast Sequence'!$A:$A,$A13,'Feast Sequence'!$F:$F) -> 2 | L13: =E13*'Weights (Feast)'!$B$18+J13*'Weights (Feast)'!$B$19+F13*'Weights (Feast)'!$B$20+G13*'Weights (Feast)'!$B$21 -> 69 | M13: =VLOOKUP(B13,'Weights (Feast)'!$A$4:$B$8,2,FALSE()) -> 60 | N13: =L13-M13 -> 9 | O13: =SUMIF('Feast Combat Ability'!$A:$A,$A13,'Feast Combat Ability'!$K:$K) -> 6 | P13: =IF(H13=0,0,K13/H13) -> 1 | Q13: =IF(COUNTIFS('Feast Combat Ability'!$A:$A,$A13,'Feast Combat Ability'!$C:$C,"Special")=0,0,P13*'Weights (Feast)'!$B$75) -> 0 | R13: =L13+O13+Q13 -> 75 | S13: =VLOOKUP(B13,'Weights (Feast)'!$A$11:$B$15,2,FALSE()) -> 60 | T13: =R13-S13 -> 15
... A19: ='Monsters Config'!A19 -> MONSTER_JELLYUDON | B19: ='Monsters Config'!B19 -> 5 | C19: ='Monsters Config'!C19 -> แมงกะพรุนอูด้ง | D19: ='Monsters Config'!D19 -> Jelly Udon | E19: ='Monsters Config'!E19 -> 40 | F19: ='Monsters Config'!G19 -> 6 | G19: ='Monsters Config'!H19 -> 6 | H19: 4 | I19: =COUNTIF('Feast Sequence'!$A:$A,$A19) -> 3 | J19: =SUMIF('Feast Sequence'!$A:$A,$A19,'Feast Sequence'!$E:$E) -> 10 | K19: =SUMIF('Feast Sequence'!$A:$A,$A19,'Feast Sequence'!$F:$F) -> 3 | L19: =E19*'Weights (Feast)'!$B$18+J19*'Weights (Feast)'!$B$19+F19*'Weights (Feast)'!$B$20+G19*'Weights (Feast)'!$B$21 -> 100 | M19: =VLOOKUP(B19,'Weights (Feast)'!$A$4:$B$8,2,FALSE()) -> 100 | N19: =L19-M19 -> 0 | O19: =SUMIF('Feast Combat Ability'!$A:$A,$A19,'Feast Combat Ability'!$K:$K) -> 27 | P19: =IF(H19=0,0,K19/H19) -> 0.75 | Q19: =IF(COUNTIFS('Feast Combat Ability'!$A:$A,$A19,'Feast Combat Ability'!$C:$C,"Special")=0,0,P19*'Weights (Feast)'!$B$75) -> 0 | R19: =L19+O19+Q19 -> 127 | S19: =VLOOKUP(B19,'Weights (Feast)'!$A$11:$B$15,2,FALSE()) -> 100 | T19: =R19-S19 -> 27

Sheet Feast Sequence
A1: Key | B1: Name | C1: Order | D1: Action | E1: ATK | F1: Charge | G1: Note
A2: MONSTER_ORANGECAT | B2: Orange Cat | C2: 1 | D2: Attack | E2: 2 | F2: 1 | G2: T1 default 1 action | base ATK 2 แบ่งลง action
A3: MONSTER_ONPIRENION | B3: Onpirenion | C3: 1 | D3: Attack | E3: 1 | F3: 1 | G3: T1 default 1 action | base ATK 1 แบ่งลง action
A4: MONSTER_MUSHROOMRAT | B4: Mushroom Rat | C4: 1 | D4: Attack | E4: 1 | F4: 1 | G4: T1 default 1 action | base ATK 1 แบ่งลง action
A5: MONSTER_CABBAGEDOG | B5: Cabbage dog | C5: 1 | D5: Attack | E5: 1 | F5: 1 | G5: T1 default 1 action | base ATK 1 แบ่งลง action
A6: MONSTER_CHERRYBIRD | B6: Cherry Bird | C6: 1 | D6: Attack | E6: 2 | F6: 1 | G6: T2 default 2 action | base ATK 4 แบ่งลง action
A7: MONSTER_CHERRYBIRD | B7: Cherry Bird | C7: 2 | D7: Attack | E7: 2 | F7: 1
A8: MONSTER_PUDDINGCRAP | B8: Pudding Crab | C8: 1 | D8: Attack | E8: 2 | F8: 1 | G8: T2 default 2 action | base ATK 3 แบ่งลง action
A9: MONSTER_PUDDINGCRAP | B9: Pudding Crab | C9: 2 | D9: Attack | E9: 1 | F9: 1
A10: MONSTER_SUGARTIGER | B10: Sugar Tiger | C10: 1 | D10: Attack | E10: 2 | F10: 1 | G10: T2 default 2 action | base ATK 4 แบ่งลง action
A11: MONSTER_SUGARTIGER | B11: Sugar Tiger | C11: 2 | D11: Attack | E11: 2 | F11: 1
A12: MONSTER_SPICYHEDGEHOG | B12: Spicy Hedgehog | C12: 1 | D12: Attack | E12: 3 | F12: 1 | G12: T3 default 2 action | base ATK 5 แบ่งลง action
A13: MONSTER_SPICYHEDGEHOG | B13: Spicy Hedgehog | C13: 2 | D13: Attack | E13: 2 | F13: 1
A14: MONSTER_BLUEFIN | B14: Bluefin In love | C14: 1 | D14: Attack | E14: 2 | F14: 1 | G14: T3 default 2 action | base ATK 4 แบ่งลง action
A15: MONSTER_BLUEFIN | B15: Bluefin In love | C15: 2 | D15: Attack | E15: 2 | F15: 1
A16: MONSTER_PIZZATURTLE | B16: Pizza Turtle | C16: 1 | D16: Attack | E16: 2 | F16: 1 | G16: T3 default 2 action | base ATK 4 แบ่งลง action
A17: MONSTER_PIZZATURTLE | B17: Pizza Turtle | C17: 2 | D17: Attack | E17: 2 | F17: 1
A18: MONSTER_DURAINBOMB | B18: Durain Bomb | C18: 1 | D18: Attack | E18: 3 | F18: 1 | G18: T3 default 2 action | base ATK 6 แบ่งลง action
A19: MONSTER_DURAINBOMB | B19: Durain Bomb | C19: 2 | D19: Attack | E19: 3 | F19: 1
A20: MONSTER_CHIVE | B20: Garlic Chives | C20: 1 | D20: Attack | E20: 3 | F20: 1 | G20: T3 default 2 action | base ATK 5 แบ่งลง action
A21: MONSTER_CHIVE | B21: Garlic Chives | C21: 2 | D21: Attack | E21: 2 | F21: 1
A22: MONSTER_BROCOLION | B22: Broco Lion | C22: 1 | D22: Attack | E22: 3 | F22: 1 | G22: T4 default 3 action | base ATK 8 แบ่งลง action
A23: MONSTER_BROCOLION | B23: Broco Lion | C23: 2 | D23: Attack | E23: 3 | F23: 1
A24: MONSTER_BROCOLION | B24: Broco Lion | C24: 3 | D24: Attack | E24: 2 | F24: 1
A25: MONSTER_BANANAOCTOPUS | B25: Banana Octopus | C25: 1 | D25: Attack | E25: 2 | F25: 1 | G25: T4 default 3 action | base ATK 6 แบ่งลง action
A26: MONSTER_BANANAOCTOPUS | B26: Banana Octopus | C26: 2 | D26: Attack | E26: 2 | F26: 1
A27: MONSTER_BANANAOCTOPUS | B27: Banana Octopus | C27: 3 | D27: Attack | E27: 2 | F27: 1
A28: MONSTER_UBEECORN | B28: Ubeecorn | C28: 1 | D28: Attack | E28: 3 | F28: 1 | G28: T4 default 3 action | base ATK 9 แบ่งลง action
A29: MONSTER_UBEECORN | B29: Ubeecorn | C29: 2 | D29: Attack | E29: 3 | F29: 1
A30: MONSTER_UBEECORN | B30: Ubeecorn | C30: 3 | D30: Attack | E30: 3 | F30: 1
A31: MONSTER_MONKEYCUPSSPICES | B31: MonkeyCupsSpices | C31: 1 | D31: Attack | E31: 2 | F31: 1 | G31: T4 default 3 action | base ATK 6 แบ่งลง action
A32: MONSTER_MONKEYCUPSSPICES | B32: MonkeyCupsSpices | C32: 2 | D32: Attack | E32: 2 | F32: 1
A33: MONSTER_MONKEYCUPSSPICES | B33: MonkeyCupsSpices | C33: 3 | D33: Attack | E33: 2 | F33: 1
A34: MONSTER_DEARBOKCHOY | B34: DearBokchoy | C34: 1 | D34: Attack | E34: 2 | F34: 1 | G34: T5 default 3 action | base ATK 5 แบ่งลง action
A35: MONSTER_DEARBOKCHOY | B35: DearBokchoy | C35: 2 | D35: Attack | E35: 2 | F35: 1
A36: MONSTER_DEARBOKCHOY | B36: DearBokchoy | C36: 3 | D36: Attack | E36: 1 | F36: 1
A37: MONSTER_JELLYUDON | B37: Jelly Udon | C37: 1 | D37: Attack | E37: 4 | F37: 1 | G37: T5 default 3 action | base ATK 10 แบ่งลง action
A38: MONSTER_JELLYUDON | B38: Jelly Udon | C38: 2 | D38: Attack | E38: 3 | F38: 1
A39: MONSTER_JELLYUDON | B39: Jelly Udon | C39: 3 | D39: Attack | E39: 3 | F39: 1

Sheet Feast Combat Ability
A1: Key | B1: Name | C1: Lane | D1: Scope | E1: Effect | F1: Trigger | G1: Verb | H1: Magnitude | I1: Target | J1: Effect Sign | K1: Effect Value | L1: Note
A2: MONSTER_PUDDINGCRAP | B2: Pudding Crab | C2: Action | D2: Combat | E2: Special: Gain 2 DEF | F2: Special | G2: Gain | H2: 2 | I2: DEF | J2: Positive | K2: =IF(D2="Grid",0,VLOOKUP(F2,'Weights (Feast)'!$A$24:$B$32,2,FALSE())*VLOOKUP(G2,'Weights (Feast)'!$A$35:$B$45,2,FALSE())*VLOOKUP(H2,'Weights (Feast)'!$A$48:$B$52,2,FALSE())*VLOOKUP(I2,'Weights (Feast)'!$A$60:$B$72,2,FALSE())*(-1)*VLOOKUP(J2,'Weights (Feast)'!$A$55:$B$57,2,FALSE())) -> 2.8125
A3: MONSTER_SUGARTIGER | B3: Sugar Tiger | C3: Action | D3: Combat | E3: Special: Gain 1 ATK | F3: Special | G3: Gain | H3: 1 | I3: ATK | J3: Positive | K3: =IF(D3="Grid",0,VLOOKUP(F3,'Weights (Feast)'!$A$24:$B$32,2,FALSE())*VLOOKUP(G3,'Weights (Feast)'!$A$35:$B$45,2,FALSE())*VLOOKUP(H3,'Weights (Feast)'!$A$48:$B$52,2,FALSE())*VLOOKUP(I3,'Weights (Feast)'!$A$60:$B$72,2,FALSE())*(-1)*VLOOKUP(J3,'Weights (Feast)'!$A$55:$B$57,2,FALSE())) -> 3.75
A4: MONSTER_SPICYHEDGEHOG | B4: Spicy Hedgehog | C4: Passive | D4: Combat | E4: On-Start: Gain 1 Thorn | F4: On-Start | G4: Gain | H4: 1 | I4: Thorn | J4: Positive | K4: =IF(D4="Grid",0,VLOOKUP(F4,'Weights (Feast)'!$A$24:$B$32,2,FALSE())*VLOOKUP(G4,'Weights (Feast)'!$A$35:$B$45,2,FALSE())*VLOOKUP(H4,'Weights (Feast)'!$A$48:$B$52,2,FALSE())*VLOOKUP(I4,'Weights (Feast)'!$A$60:$B$72,2,FALSE())*(-1)*VLOOKUP(J4,'Weights (Feast)'!$A$55:$B$57,2,FALSE())) -> 4.5
A5: MONSTER_SPICYHEDGEHOG | B5: Spicy Hedgehog | C5: Passive | D5: Combat | E5: Special: Gain 1 Thorn | F5: Special | G5: Gain | H5: 1 | I5: Thorn | J5: Positive | K5: =IF(D5="Grid",0,VLOOKUP(F5,'Weights (Feast)'!$A$24:$B$32,2,FALSE())*VLOOKUP(G5,'Weights (Feast)'!$A$35:$B$45,2,FALSE())*VLOOKUP(H5,'Weights (Feast)'!$A$48:$B$52,2,FALSE())*VLOOKUP(I5,'Weights (Feast)'!$A$60:$B$72,2,FALSE())*(-1)*VLOOKUP(J5,'Weights (Feast)'!$A$55:$B$57,2,FALSE())) -> 5.625
A6: MONSTER_BLUEFIN | B6: Bluefin In love | C6: Passive | D6: Combat | E6: On-Damaged: Convert 3 HP to 1 SPD | F6: On-Damaged | G6: Convert | H6: 3 | I6: SPD | J6: Positive | K6: =IF(D6="Grid",0,VLOOKUP(F6,'Weights (Feast)'!$A$24:$B$32,2,FALSE())*VLOOKUP(G6,'Weights (Feast)'!$A$35:$B$45,2,FALSE())*VLOOKUP(H6,'Weights (Feast)'!$A$48:$B$52,2,FALSE())*VLOOKUP(I6,'Weights (Feast)'!$A$60:$B$72,2,FALSE())*(-1)*VLOOKUP(J6,'Weights (Feast)'!$A$55:$B$57,2,FALSE())) -> 9
A7: MONSTER_BLUEFIN | B7: Bluefin In love | C7: Passive | D7: Combat | E7: Special: Convert 3 HP to 1 SPD | F7: On-Damaged | G7: Convert | H7: 3 | I7: SPD | J7: Positive | K7: =IF(D7="Grid",0,VLOOKUP(F7,'Weights (Feast)'!$A$24:$B$32,2,FALSE())*VLOOKUP(G7,'Weights (Feast)'!$A$35:$B$45,2,FALSE())*VLOOKUP(H7,'Weights (Feast)'!$A$48:$B$52,2,FALSE())*VLOOKUP(I7,'Weights (Feast)'!$A$60:$B$72,2,FALSE())*(-1)*VLOOKUP(J7,'Weights (Feast)'!$A$55:$B$57,2,FALSE())) -> 9
A8: MONSTER_PIZZATURTLE | B8: Pizza Turtle | C8: Passive | D8: Combat | E8: On-Damaged: Armor 1 | F8: On-Damaged | G8: Armor | H8: 1 | I8: Armor | J8: Positive | K8: =IF(D8="Grid",0,VLOOKUP(F8,'Weights (Feast)'!$A$24:$B$32,2,FALSE())*VLOOKUP(G8,'Weights (Feast)'!$A$35:$B$45,2,FALSE())*VLOOKUP(H8,'Weights (Feast)'!$A$48:$B$52,2,FALSE())*VLOOKUP(I8,'Weights (Feast)'!$A$60:$B$72,2,FALSE())*(-1)*VLOOKUP(J8,'Weights (Feast)'!$A$55:$B$57,2,FALSE())) -> 11.25
A9: MONSTER_DURAINBOMB | B9: Durain Bomb | C9: Passive | D9: Combat | E9: On-Start: Thorn 1 | F9: On-Start | G9: Thorn | H9: 1 | I9: Thorn | J9: Positive | K9: =IF(D9="Grid",0,VLOOKUP(F9,'Weights (Feast)'!$A$24:$B$32,2,FALSE())*VLOOKUP(G9,'Weights (Feast)'!$A$35:$B$45,2,FALSE())*VLOOKUP(H9,'Weights (Feast)'!$A$48:$B$52,2,FALSE())*VLOOKUP(I9,'Weights (Feast)'!$A$60:$B$72,2,FALSE())*(-1)*VLOOKUP(J9,'Weights (Feast)'!$A$55:$B$57,2,FALSE())) -> 9
A10: MONSTER_DURAINBOMB | B10: Durain Bomb | C10: Action | D10: Combat | E10: Special: Eater 1 | F10: On-Hit | G10: Eater | H10: 1 | I10: Eater | J10: Positive | K10: =IF(D10="Grid",0,VLOOKUP(F10,'Weights (Feast)'!$A$24:$B$32,2,FALSE())*VLOOKUP(G10,'Weights (Feast)'!$A$35:$B$45,2,FALSE())*VLOOKUP(H10,'Weights (Feast)'!$A$48:$B$52,2,FALSE())*VLOOKUP(I10,'Weights (Feast)'!$A$60:$B$72,2,FALSE())*(-1)*VLOOKUP(J10,'Weights (Feast)'!$A$55:$B$57,2,FALSE())) -> 18 | L10: Scope=Combat ไว้ก่อน — confirm ว่า Eater เป็น combat หรือ grid
A11: MONSTER_CHIVE | B11: Garlic Chives | C11: Action | D11: Combat | E11: On-Hit: Gain 1 ATK | F11: On-Hit | G11: Gain | H11: 1 | I11: ATK | J11: Positive | K11: =IF(D11="Grid",0,VLOOKUP(F11,'Weights (Feast)'!$A$24:$B$32,2,FALSE())*VLOOKUP(G11,'Weights (Feast)'!$A$35:$B$45,2,FALSE())*VLOOKUP(H11,'Weights (Feast)'!$A$48:$B$52,2,FALSE())*VLOOKUP(I11,'Weights (Feast)'!$A$60:$B$72,2,FALSE())*(-1)*VLOOKUP(J11,'Weights (Feast)'!$A$55:$B$57,2,FALSE())) -> 6
A12: MONSTER_BROCOLION | B12: Broco Lion | C12: Passive | D12: Combat | E12: On-Exposed: Gain 2 ATK | F12: On-Exposed | G12: Gain | H12: 2 | I12: ATK | J12: Positive | K12: =IF(D12="Grid",0,VLOOKUP(F12,'Weights (Feast)'!$A$24:$B$32,2,FALSE())*VLOOKUP(G12,'Weights (Feast)'!$A$35:$B$45,2,FALSE())*VLOOKUP(H12,'Weights (Feast)'!$A$48:$B$52,2,FALSE())*VLOOKUP(I12,'Weights (Feast)'!$A$60:$B$72,2,FALSE())*(-1)*VLOOKUP(J12,'Weights (Feast)'!$A$55:$B$57,2,FALSE())) -> 3.375
A13: MONSTER_BROCOLION | B13: Broco Lion | C13: Passive | D13: Combat | E13: On-Half: Gain 2 SPD | F13: On-Half | G13: Gain | H13: 2 | I13: SPD | J13: Positive | K13: =IF(D13="Grid",0,VLOOKUP(F13,'Weights (Feast)'!$A$24:$B$32,2,FALSE())*VLOOKUP(G13,'Weights (Feast)'!$A$35:$B$45,2,FALSE())*VLOOKUP(H13,'Weights (Feast)'!$A$48:$B$52,2,FALSE())*VLOOKUP(I13,'Weights (Feast)'!$A$60:$B$72,2,FALSE())*(-1)*VLOOKUP(J13,'Weights (Feast)'!$A$55:$B$57,2,FALSE())) -> 3.375
A14: MONSTER_BANANAOCTOPUS | B14: Banana Octopus | C14: Passive | D14: Combat | E14: On-Damaged: Gain 2 ATK | F14: On-Damaged | G14: Gain | H14: 2 | I14: ATK | J14: Positive | K14: =IF(D14="Grid",0,VLOOKUP(F14,'Weights (Feast)'!$A$24:$B$32,2,FALSE())*VLOOKUP(G14,'Weights (Feast)'!$A$35:$B$45,2,FALSE())*VLOOKUP(H14,'Weights (Feast)'!$A$48:$B$52,2,FALSE())*VLOOKUP(I14,'Weights (Feast)'!$A$60:$B$72,2,FALSE())*(-1)*VLOOKUP(J14,'Weights (Feast)'!$A$55:$B$57,2,FALSE())) -> 6.75
A15: MONSTER_UBEECORN | B15: Ubeecorn | C15: Action | D15: Combat | E15: On-Hit: Restore 2 HP | F15: On-Hit | G15: Restore | H15: 2 | I15: HP | J15: Positive | K15: =IF(D15="Grid",0,VLOOKUP(F15,'Weights (Feast)'!$A$24:$B$32,2,FALSE())*VLOOKUP(G15,'Weights (Feast)'!$A$35:$B$45,2,FALSE())*VLOOKUP(H15,'Weights (Feast)'!$A$48:$B$52,2,FALSE())*VLOOKUP(I15,'Weights (Feast)'!$A$60:$B$72,2,FALSE())*(-1)*VLOOKUP(J15,'Weights (Feast)'!$A$55:$B$57,2,FALSE())) -> 4.5
A16: MONSTER_UBEECORN | B16: Ubeecorn | C16: Passive | D16: Combat | E16: On-Half: Shield 1 | F16: On-Half | G16: Shield | H16: 1 | I16: Shield | J16: Positive | K16: =IF(D16="Grid",0,VLOOKUP(F16,'Weights (Feast)'!$A$24:$B$32,2,FALSE())*VLOOKUP(G16,'Weights (Feast)'!$A$35:$B$45,2,FALSE())*VLOOKUP(H16,'Weights (Feast)'!$A$48:$B$52,2,FALSE())*VLOOKUP(I16,'Weights (Feast)'!$A$60:$B$72,2,FALSE())*(-1)*VLOOKUP(J16,'Weights (Feast)'!$A$55:$B$57,2,FALSE())) -> 5.625
A17: MONSTER_MONKEYCUPSSPICES | B17: MonkeyCupsSpices | C17: Passive | D17: Combat | E17: On-Half: Thorn 2 | F17: On-Half | G17: Thorn | H17: 2 | I17: Thorn | J17: Positive | K17: =IF(D17="Grid",0,VLOOKUP(F17,'Weights (Feast)'!$A$24:$B$32,2,FALSE())*VLOOKUP(G17,'Weights (Feast)'!$A$35:$B$45,2,FALSE())*VLOOKUP(H17,'Weights (Feast)'!$A$48:$B$52,2,FALSE())*VLOOKUP(I17,'Weights (Feast)'!$A$60:$B$72,2,FALSE())*(-1)*VLOOKUP(J17,'Weights (Feast)'!$A$55:$B$57,2,FALSE())) -> 10.125
A18: MONSTER_DEARBOKCHOY | B18: DearBokchoy | C18: Passive | D18: Combat | E18: On-Start: Thorn 2 | F18: On-Start | G18: Thorn | H18: 2 | I18: Thorn | J18: Positive | K18: =IF(D18="Grid",0,VLOOKUP(F18,'Weights (Feast)'!$A$24:$B$32,2,FALSE())*VLOOKUP(G18,'Weights (Feast)'!$A$35:$B$45,2,FALSE())*VLOOKUP(H18,'Weights (Feast)'!$A$48:$B$52,2,FALSE())*VLOOKUP(I18,'Weights (Feast)'!$A$60:$B$72,2,FALSE())*(-1)*VLOOKUP(J18,'Weights (Feast)'!$A$55:$B$57,2,FALSE())) -> 13.5
A19: MONSTER_DEARBOKCHOY | B19: DearBokchoy | C19: Action | D19: Combat | E19: Special: Restore 2 HP | F19: On-Hit | G19: Restore | H19: 2 | I19: HP | J19: Positive | K19: =IF(D19="Grid",0,VLOOKUP(F19,'Weights (Feast)'!$A$24:$B$32,2,FALSE())*VLOOKUP(G19,'Weights (Feast)'!$A$35:$B$45,2,FALSE())*VLOOKUP(H19,'Weights (Feast)'!$A$48:$B$52,2,FALSE())*VLOOKUP(I19,'Weights (Feast)'!$A$60:$B$72,2,FALSE())*(-1)*VLOOKUP(J19,'Weights (Feast)'!$A$55:$B$57,2,FALSE())) -> 4.5
A20: MONSTER_JELLYUDON | B20: Jelly Udon | C20: Passive | D20: Combat | E20: On-Exposed: Thorn 2 | F20: On-Exposed | G20: Thorn | H20: 2 | I20: Thorn | J20: Positive | K20: =IF(D20="Grid",0,VLOOKUP(F20,'Weights (Feast)'!$A$24:$B$32,2,FALSE())*VLOOKUP(G20,'Weights (Feast)'!$A$35:$B$45,2,FALSE())*VLOOKUP(H20,'Weights (Feast)'!$A$48:$B$52,2,FALSE())*VLOOKUP(I20,'Weights (Feast)'!$A$60:$B$72,2,FALSE())*(-1)*VLOOKUP(J20,'Weights (Feast)'!$A$55:$B$57,2,FALSE())) -> 10.125
A21: MONSTER_JELLYUDON | B21: Jelly Udon | C21: Passive | D21: Combat | E21: On-Half: Armor 1 | F21: On-Half | G21: Armor | H21: 2 | I21: Armor | J21: Positive | K21: =IF(D21="Grid",0,VLOOKUP(F21,'Weights (Feast)'!$A$24:$B$32,2,FALSE())*VLOOKUP(G21,'Weights (Feast)'!$A$35:$B$45,2,FALSE())*VLOOKUP(H21,'Weights (Feast)'!$A$48:$B$52,2,FALSE())*VLOOKUP(I21,'Weights (Feast)'!$A$60:$B$72,2,FALSE())*(-1)*VLOOKUP(J21,'Weights (Feast)'!$A$55:$B$57,2,FALSE())) -> 8.4375
A22: MONSTER_JELLYUDON | B22: Jelly Udon | C22: Passive | D22: Combat | E22: On-Half: Armor 2 | F22: On-Half | G22: Armor | H22: 2 | I22: Armor | J22: Positive | K22: =IF(D22="Grid",0,VLOOKUP(F22,'Weights (Feast)'!$A$24:$B$32,2,FALSE())*VLOOKUP(G22,'Weights (Feast)'!$A$35:$B$45,2,FALSE())*VLOOKUP(H22,'Weights (Feast)'!$A$48:$B$52,2,FALSE())*VLOOKUP(I22,'Weights (Feast)'!$A$60:$B$72,2,FALSE())*(-1)*VLOOKUP(J22,'Weights (Feast)'!$A$55:$B$57,2,FALSE())) -> 8.4375

Sheet Feast Grid Ability
A1: Key | B1: Name | C1: Lane | D1: Scope | E1: Effect | F1: Trigger | G1: Verb | H1: Magnitude | I1: Target | J1: Effect Sign | K1: Effect Value | L1: Note
A2: MONSTER_CHERRYBIRD | B2: Cherry Bird | C2: Passive | D2: Combat | E2: On-Start: Thorn 1 | F2: On-Start | G2: Gain | H2: 1 | I2: Thorn | J2: Positive | K2: =IF(D2="Grid",0,VLOOKUP(F2,'Weights (Feast)'!$A$24:$B$32,2,FALSE())*VLOOKUP(G2,'Weights (Feast)'!$A$35:$B$45,2,FALSE())*VLOOKUP(H2,'Weights (Feast)'!$A$48:$B$52,2,FALSE())*VLOOKUP(I2,'Weights (Feast)'!$A$60:$B$72,2,FALSE())*(-1)*VLOOKUP(J2,'Weights (Feast)'!$A$55:$B$57,2,FALSE())) -> 4.5 | L2: Grid keyword — ไม่มีผลใน combat จึงไม่คิด EV; ไม่ควรแปลงเป็น Special
A3: MONSTER_SPICYHEDGEHOG | B3: Spicy Hedgehog | C3: Passive | D3: Grid | E3: Battlecry: Taunt 2 | F3: Battlecry | G3: Taunt | H3: 2 | I3: Taunt | J3: None | K3: =IF(D3="Grid",0,VLOOKUP(F3,'Weights (Feast)'!$A$24:$B$32,2,FALSE())*VLOOKUP(G3,'Weights (Feast)'!$A$35:$B$45,2,FALSE())*VLOOKUP(H3,'Weights (Feast)'!$A$48:$B$52,2,FALSE())*VLOOKUP(I3,'Weights (Feast)'!$A$60:$B$72,2,FALSE())*(-1)*VLOOKUP(J3,'Weights (Feast)'!$A$55:$B$57,2,FALSE())) -> 0 | L3: Grid keyword — ไม่มีผลใน combat จึงไม่คิด EV; ไม่ควรแปลงเป็น Special
A4: MONSTER_BLUEFIN | B4: Bluefin In love | C4: Passive | D4: Grid | E4: Battlecry: Freezer 2 | F4: Battlecry | G4: Freezer | H4: 2 | I4: Freezer | J4: None | K4: =IF(D4="Grid",0,VLOOKUP(F4,'Weights (Feast)'!$A$24:$B$32,2,FALSE())*VLOOKUP(G4,'Weights (Feast)'!$A$35:$B$45,2,FALSE())*VLOOKUP(H4,'Weights (Feast)'!$A$48:$B$52,2,FALSE())*VLOOKUP(I4,'Weights (Feast)'!$A$60:$B$72,2,FALSE())*(-1)*VLOOKUP(J4,'Weights (Feast)'!$A$55:$B$57,2,FALSE())) -> 0 | L4: Grid keyword — ไม่มีผลใน combat จึงไม่คิด EV; ไม่ควรแปลงเป็น Special
A5: MONSTER_PIZZATURTLE | B5: Pizza Turtle | C5: Passive | D5: Grid | E5: Battlecry: Taunt 3 | F5: Battlecry | G5: Taunt | H5: 3 | I5: Taunt | J5: None | K5: =IF(D5="Grid",0,VLOOKUP(F5,'Weights (Feast)'!$A$24:$B$32,2,FALSE())*VLOOKUP(G5,'Weights (Feast)'!$A$35:$B$45,2,FALSE())*VLOOKUP(H5,'Weights (Feast)'!$A$48:$B$52,2,FALSE())*VLOOKUP(I5,'Weights (Feast)'!$A$60:$B$72,2,FALSE())*(-1)*VLOOKUP(J5,'Weights (Feast)'!$A$55:$B$57,2,FALSE())) -> 0 | L5: Grid keyword — ไม่มีผลใน combat จึงไม่คิด EV; ไม่ควรแปลงเป็น Special
A6: MONSTER_CHIVE | B6: กุ้ยช่ายสด | C6: Passive | D6: Grid | E6: Death: Freezer 2 | F6: Death | G6: Freezer | H6: 2 | I6: Freezer | J6: None | K6: =IF(D6="Grid",0,VLOOKUP(F6,'Weights (Feast)'!$A$24:$B$32,2,FALSE())*VLOOKUP(G6,'Weights (Feast)'!$A$35:$B$45,2,FALSE())*VLOOKUP(H6,'Weights (Feast)'!$A$48:$B$52,2,FALSE())*VLOOKUP(I6,'Weights (Feast)'!$A$60:$B$72,2,FALSE())*(-1)*VLOOKUP(J6,'Weights (Feast)'!$A$55:$B$57,2,FALSE())) -> 0 | L6: Grid keyword — ไม่มีผลใน combat จึงไม่คิด EV; ไม่ควรแปลงเป็น Special
A7: MONSTER_BANANAOCTOPUS | B7: Banana Octopus | C7: Passive | D7: Grid | E7: Battlecry: Taunt 2 | F7: Battlecry | G7: Taunt | H7: 2 | I7: Taunt | J7: None | K7: =IF(D7="Grid",0,VLOOKUP(F7,'Weights (Feast)'!$A$24:$B$32,2,FALSE())*VLOOKUP(G7,'Weights (Feast)'!$A$35:$B$45,2,FALSE())*VLOOKUP(H7,'Weights (Feast)'!$A$48:$B$52,2,FALSE())*VLOOKUP(I7,'Weights (Feast)'!$A$60:$B$72,2,FALSE())*(-1)*VLOOKUP(J7,'Weights (Feast)'!$A$55:$B$57,2,FALSE())) -> 0 | L7: Grid keyword — ไม่มีผลใน combat จึงไม่คิด EV; ไม่ควรแปลงเป็น Special
A8: MONSTER_MONKEYCUPSSPICES | B8: MonkeyCupsSpices | C8: Passive | D8: Grid | E8: Battlecry: Freezer 2 | F8: Battlecry | G8: Freezer | H8: 2 | I8: Freezer | J8: None | K8: =IF(D8="Grid",0,VLOOKUP(F8,'Weights (Feast)'!$A$24:$B$32,2,FALSE())*VLOOKUP(G8,'Weights (Feast)'!$A$35:$B$45,2,FALSE())*VLOOKUP(H8,'Weights (Feast)'!$A$48:$B$52,2,FALSE())*VLOOKUP(I8,'Weights (Feast)'!$A$60:$B$72,2,FALSE())*(-1)*VLOOKUP(J8,'Weights (Feast)'!$A$55:$B$57,2,FALSE())) -> 0 | L8: Grid keyword — ไม่มีผลใน combat จึงไม่คิด EV; ไม่ควรแปลงเป็น Special
A9: MONSTER_DEARBOKCHOY | B9: DearBokchoy | C9: Passive | D9: Grid | E9: Battlecry: Freezer 3 | F9: Battlecry | G9: Freezer | H9: 3 | I9: Freezer | J9: None | K9: =IF(D9="Grid",0,VLOOKUP(F9,'Weights (Feast)'!$A$24:$B$32,2,FALSE())*VLOOKUP(G9,'Weights (Feast)'!$A$35:$B$45,2,FALSE())*VLOOKUP(H9,'Weights (Feast)'!$A$48:$B$52,2,FALSE())*VLOOKUP(I9,'Weights (Feast)'!$A$60:$B$72,2,FALSE())*(-1)*VLOOKUP(J9,'Weights (Feast)'!$A$55:$B$57,2,FALSE())) -> 0 | L9: Grid keyword — ไม่มีผลใน combat จึงไม่คิด EV; ไม่ควรแปลงเป็น Special
A10: MONSTER_JELLYUDON | B10: Jelly Udon | C10: Passive | D10: Grid | E10: Battlecry: Taunt 3 | F10: Battlecry | G10: Taunt | H10: 3 | I10: Taunt | J10: None | K10: =IF(D10="Grid",0,VLOOKUP(F10,'Weights (Feast)'!$A$24:$B$32,2,FALSE())*VLOOKUP(G10,'Weights (Feast)'!$A$35:$B$45,2,FALSE())*VLOOKUP(H10,'Weights (Feast)'!$A$48:$B$52,2,FALSE())*VLOOKUP(I10,'Weights (Feast)'!$A$60:$B$72,2,FALSE())*(-1)*VLOOKUP(J10,'Weights (Feast)'!$A$55:$B$57,2,FALSE())) -> 0 | L10: Grid keyword — ไม่มีผลใน combat จึงไม่คิด EV; ไม่ควรแปลงเป็น Special
